<?xml version="1.0"?>
<robot
    xmlns:xacro="http://www.ros.org/wiki/xacro"
    name="hbosuit">

    <xacro:include filename="$(find hbo)/urdf/common.urdf.xacro" />
    <xacro:include filename="$(find hbo)/urdf/body/upper_body_imu.urdf.xacro" />
    <xacro:include filename="$(find zelmet)/urdf/zelmet.urdf.xacro" />

    <!-- Note: Base Link is the back of the skull, right where the Zelmet strap is. -->

    <!-- Physical Constant Macros -->
    <xacro:property name="M_PI"    value="3.1415926535897931" />
    <xacro:property name="M_41deg" value="0.7155849933176751265387132150803312" />
    <xacro:property name="M_16deg" value="0.2792526803190927a32307790522958" />

    <!-- IMU placement relative to chest --> 
    <xacro:property name="imu_x" value="0" /> 
    <xacro:property name="imu_y" value="0" />
    <xacro:property name="imu_z" value="0" />

    <xacro:property name="imu_roll" value="0" /> 
    <xacro:property name="imu_pitch" value="0" />
    <xacro:property name="imu_yaw" value="0" />

    <!-- Body dimensions --> 
    <xacro:property name="w_shoulder" value=".3048" /> 
    <xacro:property name="l_upper_arm" value=".3048" />
    <xacro:property name="l_forearm" value=".2667" />
    <xacro:property name="r_upper_arm" value=".0424" />
    <xacro:property name="r_forearm" value="0.03436155221" />
    <xacro:property name="l_chest" value="0.1016" />

    <!-- Chest -->
    <link name="origin_link">
    </link>

     <joint name="chest_yaw" type="continuous">
         <parent link="origin_link"/>
         <child link="chest_yaw_link"/>
         <axis xyz="0 0 1"/>
         <origin xyz="0 0 0"/>
    </joint>

    <link name="chest_yaw_link">
    </link>

    <joint name="chest_pitch" type="continuous">
         <parent link="chest_yaw_link"/>
         <child link="chest_pitch_link"/>
         <axis xyz="0 1 0"/>
         <origin xyz="0 0 0"/>
    </joint> 

    <link name="chest_pitch_link">
    </link>

    <joint name="chest_roll" type="continuous">
         <parent link="chest_pitch_link"/>
         <child link="chest_link"/>
         <axis xyz="1 0 0"/>
         <origin xyz="0 0 0"/>
    </joint>

    <link name="chest_link">
        <visual>
            <origin xyz="0 0 0" rpy="0 0 0" />
            <geometry>
                 <box size="${w_shoulder/2} ${w_shoulder} ${w_shoulder/2}" length="${l_chest}" />
             </geometry>
            <material name="DarkGrey"/>
        </visual>
    </link>

    <!-- IMU -->
    <xacro:um7_imu_v0
        name="imu_chest" 
        parent="chest_link">
        <origin 
            xyz="${imu_x} ${imu_y} ${imu_z}" 
            rpy="${imu_roll} ${imu_pitch} ${imu_yaw}" /> 
    </xacro:um7_imu_v0> 

    <joint name="helmet_yaw" type="continuous">
         <parent link="chest_link"/>
         <child link="helmet_yaw_link"/>
         <axis xyz="0 0 1"/>
         <origin xyz="0 0 .2"/>
    </joint>
    <link name="helmet_yaw_link">
    </link>
    <joint name="helmet_pitch" type="continuous">
         <parent link="helmet_yaw_link"/>
         <child link="helmet_pitch_link"/>
         <axis xyz="0 1 0"/>
         <origin xyz="0 0 0"/>
    </joint>
    <link name="helmet_pitch_link">
    </link>
    <joint name="helmet_roll" type="continuous">
         <parent link="helmet_pitch_link"/>
         <child link="helmet_link"/>
         <axis xyz="1 0 0"/>
         <origin xyz="0 0 0"/>
    </joint>
    <xacro:zelmet />

    <!-- Shoulder -->
     <joint name="right_shoulder_yaw" type="continuous">
         <parent link="chest_link"/>
         <child link="rshoulder_yaw_link"/>
         <axis xyz="0 0 1"/>
         <origin xyz="0 ${-w_shoulder/2} 0" rpy="0 0 ${-M_PI/2}"/>
       </joint>
    <link name="rshoulder_yaw_link">
    </link>
    <joint name="right_shoulder_pitch" type="continuous">
         <parent link="rshoulder_yaw_link"/>
         <child link="rshoulder_pitch_link"/>
         <axis xyz="0 1 0"/>
         <origin xyz="0 0 0"/>
       </joint> 
    <link name="rshoulder_pitch_link">
    </link>
    <joint name="right_shoulder_roll" type="continuous">
         <parent link="rshoulder_pitch_link"/>
         <child link="right_upper_arm_link"/>
         <axis xyz="1 0 0"/>
         <origin xyz="0 0 0"/>
       </joint>
    <!-- Upper arm -->
    <link name="right_upper_arm_link">
        <visual>
            <origin xyz="${w_shoulder/2} 0 0" rpy="0 ${M_PI/2} 0" />
            <geometry>
                 <cylinder radius="${r_upper_arm}" length="${l_upper_arm}" />
             </geometry>
            <material name="DarkGrey"/>
        </visual>
   </link> 
    <!-- IMU -->
    <xacro:um7_imu_v0
        name="imu_upper_right_arm" 
        parent="right_upper_arm_link">
        <origin 
            xyz="${imu_x} ${imu_y} ${imu_z}" 
            rpy="${imu_roll} ${imu_pitch} ${imu_yaw}" /> 
    </xacro:um7_imu_v0> 

    <!-- Elbow -->
    <joint name="right_elbow" type="continuous">
         <parent link="right_upper_arm_link"/>
         <child link="right_forearm_link"/>
         <axis xyz="0 1 0"/>
         <origin xyz="${l_upper_arm} 0 0"/>
    </joint>

    <!-- Forearm -->
    <link name="right_forearm_link">
        <visual>
           <origin xyz="${l_forearm/2} 0 0" rpy="0 ${M_PI/2} 0" />
            <geometry>
                 <cylinder radius="${r_forearm}" length="${l_forearm}" />
             </geometry>
            <material name="DarkGrey"/>
        </visual>
    </link> 

    <!-- IMU -->
    <xacro:um7_imu_v0
        name="imu_right_forearm" 
        parent="right_forearm_link">
        <origin 
            xyz="${imu_x} ${imu_y} ${imu_z}" 
            rpy="${imu_roll} ${imu_pitch} ${imu_yaw}" /> 
    </xacro:um7_imu_v0> 
<!-- Shoulder -->
     <joint name="left_shoulder_yaw" type="continuous">
         <parent link="chest_link"/>
         <child link="lshoulder_yaw_link"/>
         <axis xyz="0 0 1"/>
         <origin xyz="0 ${w_shoulder/2} 0" rpy="0 0 ${-M_PI/2}"/>
       </joint>
    <link name="lshoulder_yaw_link">
    </link>
    <joint name="left_shoulder_pitch" type="continuous">
         <parent link="lshoulder_yaw_link"/>
         <child link="lshoulder_pitch_link"/>
         <axis xyz="0 1 0"/>
         <origin xyz="0 0 0"/>
       </joint> 
    <link name="lshoulder_pitch_link">
    </link>
    <joint name="left_shoulder_roll" type="continuous">
         <parent link="lshoulder_pitch_link"/>
         <child link="left_upper_arm_link"/>
         <axis xyz="1 0 0"/>
         <origin xyz="0 0 0"/>
       </joint>
    <!-- Upper arm -->
    <link name="left_upper_arm_link">
        <visual>
            <origin xyz="${-w_shoulder/2} 0 0" rpy="0 ${M_PI/2} 0" />
            <geometry>
                 <cylinder radius="${r_upper_arm}" length="${l_upper_arm}" />
             </geometry>
            <material name="DarkGrey"/>
        </visual>
   </link> 
    <!-- IMU -->
    <xacro:um7_imu_v0
        name="imu_upper_left_arm" 
        parent="origin_link">
        <origin 
            xyz="${imu_x} ${imu_y} ${imu_z}" 
            rpy="${imu_roll} ${imu_pitch} ${imu_yaw}" /> 
    </xacro:um7_imu_v0> 

    <!-- Elbow -->
    <joint name="left_elbow" type="continuous">
         <parent link="left_upper_arm_link"/>
         <child link="left_forearm_link"/>
         <axis xyz="0 1 0"/>
         <origin xyz="${-l_upper_arm} 0 0"/>
    </joint>

    <!-- Forearm -->
    <link name="left_forearm_link">
        <visual>
           <origin xyz="${-l_forearm/2} 0 0" rpy="0 ${M_PI/2} 0" />
            <geometry>
                 <cylinder radius="${r_forearm}" length="${l_forearm}" />
             </geometry>
            <material name="DarkGrey"/>
        </visual>
    </link> 

    <!-- IMU -->
    <xacro:um7_imu_v0
        name="imu_left_forearm" 
        parent="origin_link">
        <origin 
            xyz="${imu_x} ${imu_y} ${imu_z}" 
            rpy="${imu_roll} ${imu_pitch} ${imu_yaw}" /> 
    </xacro:um7_imu_v0> 

</robot>
